# AnalysisAndProvisionOfEventProcessing
### Анализ и обеспечение обработки исключительных ситуаций в C# с примерами и приложением

Обработка исключений в C# является ключевой составляющей разработки программного обеспечения, обеспечивающей стабильность и предсказуемость работы приложения. Исключения могут возникать по различным причинам — деление на ноль, выход за пределы массива, ошибки ввода-вывода и т. д. Важно правильно их обрабатывать, чтобы программа не завершалась аварийно, а также для того, чтобы пользователи получали полезные сообщения об ошибках.

### 1. Основы обработки исключений в C#

Обработка исключений в C# осуществляется с помощью конструкции `try-catch-finally`, где:
- **`try`** — блок, в котором может возникнуть исключение.
- **`catch`** — блок для перехвата и обработки исключений.
- **`finally`** — блок, который выполняется всегда, независимо от того, произошло ли исключение или нет (например, для очистки ресурсов).

#### Пример простого использования:

```csharp
try
{
    int result = 10 / 0;  // Это приведет к исключению деления на ноль
}
catch (DivideByZeroException ex)
{
    Console.WriteLine("Ошибка: Деление на ноль.");
}
finally
{
    Console.WriteLine("Блок finally всегда выполняется.");
}
```

### 2. Типы исключений

В C# есть множество встроенных типов исключений. Некоторые из наиболее часто используемых:
- **`DivideByZeroException`** — исключение при попытке деления на ноль.
- **`IndexOutOfRangeException`** — исключение при попытке доступа к элементу массива по недопустимому индексу.
- **`FileNotFoundException`** — исключение при попытке доступа к несуществующему файлу.
- **`NullReferenceException`** — исключение при попытке обращения к объекту, равному `null`.
- **`IOException`** — исключение при ошибках ввода-вывода.

#### Пример обработки нескольких типов исключений:

```csharp
try
{
    int[] numbers = new int[3];
    numbers[5] = 10;  // Это вызовет исключение IndexOutOfRangeException
}
catch (IndexOutOfRangeException ex)
{
    Console.WriteLine("Ошибка: Индекс выходит за пределы массива.");
}
catch (Exception ex)
{
    Console.WriteLine("Произошла общая ошибка: " + ex.Message);
}
```

### 3. Генерация собственных исключений

C# позволяет генерировать свои собственные исключения, что полезно в случае, если необходимо управлять специфическими ошибками в вашем приложении.

```csharp
public class InvalidAgeException : Exception
{
    public InvalidAgeException(string message) : base(message) { }
}

try
{
    int age = -5;
    if (age < 0)
    {
        throw new InvalidAgeException("Возраст не может быть отрицательным.");
    }
}
catch (InvalidAgeException ex)
{
    Console.WriteLine(ex.Message);
}
```

### 4. Работа с ресурсами

При работе с внешними ресурсами (файлы, соединения с базами данных) важно не только перехватывать исключения, но и правильно освобождать ресурсы, даже если возникла ошибка. Для этого используется конструкция `using`, которая автоматически вызывает метод `Dispose`.

```csharp
using (StreamReader reader = new StreamReader("data.txt"))
{
    string content = reader.ReadToEnd();
    Console.WriteLine(content);
}  // reader.Dispose() вызывается автоматически
```

### 5. Логирование ошибок

Для эффективной диагностики ошибок необходимо логировать их, записывая информацию о произошедших исключениях в файл или базу данных. В C# можно использовать стандартное логирование или сторонние библиотеки, такие как **NLog** или **Serilog**.

Пример простого логирования ошибок:

```csharp
try
{
    int result = 10 / 0;
}
catch (Exception ex)
{
    Console.WriteLine($"Ошибка: {ex.Message}");
    // Логирование в файл или базу данных
}
```

### 6. Многозадачность и обработка исключений в асинхронных задачах

При работе с многозадачностью или асинхронным кодом важно обрабатывать исключения в каждом потоке или задаче, так как исключения в асинхронных задачах не передаются в основной поток.

Пример с асинхронной задачей:

```csharp
Task.Run(() =>
{
    try
    {
        int[] numbers = new int[2];
        numbers[5] = 10;  // Это приведет к исключению
    }
    catch (Exception ex)
    {
        Console.WriteLine($"Ошибка в асинхронной задаче: {ex.Message}");
    }
});
```

### Пример приложения с полной обработкой исключений

Давайте разработаем простое консольное приложение на C#, которое будет выполнять следующие задачи:
1. Запрашивать у пользователя два числа.
2. Делить одно число на другое.
3. Записывать результат в файл.
4. Обрабатывать возможные исключения (деление на ноль, неверный ввод, ошибка записи в файл).

```csharp
using System;
using System.IO;

class Program
{
    static void Main()
    {
        try
        {
            // Запрос чисел у пользователя
            Console.Write("Введите первое число: ");
            int num1 = Convert.ToInt32(Console.ReadLine());

            Console.Write("Введите второе число: ");
            int num2 = Convert.ToInt32(Console.ReadLine());

            // Выполнение деления
            int result = Divide(num1, num2);
            Console.WriteLine($"Результат деления: {result}");

            // Запись результата в файл
            WriteResultToFile(result);
        }
        catch (FormatException ex)
        {
            // Логируем ошибку, выводим подробности
            Console.WriteLine($"Ошибка: Введите корректные числа. {ex.Message}");
        }
        catch (DivideByZeroException ex)
        {
            // Логируем ошибку деления на ноль
            Console.WriteLine($"Ошибка: Деление на ноль. {ex.Message}");
        }
        catch (IOException ex)
        {
            // Логируем ошибку записи в файл
            Console.WriteLine($"Ошибка записи в файл: {ex.Message}");
        }
        catch (Exception ex)
        {
            // Логируем любые другие ошибки
            Console.WriteLine($"Произошла непредвиденная ошибка: {ex.Message}");
        }
        finally
        {
            Console.WriteLine("Программа завершена.");
        }
    }

    // Метод для деления
    static int Divide(int num1, int num2)
    {
        if (num2 == 0)
        {
            throw new DivideByZeroException("Невозможно делить на ноль.");
        }
        return num1 / num2;
    }

    // Метод для записи результата в файл
    static void WriteResultToFile(int result)
    {
        string path = "result.txt";
        try
        {
            File.WriteAllText(path, $"Результат деления: {result}");
            Console.WriteLine($"Результат успешно записан в файл {path}.");
        }
        catch (IOException ex)
        {
            // Логируем ошибку записи в файл
            throw new IOException("Ошибка при записи в файл.", ex);
        }
    }
}

```

### Объяснение кода:
1. **Запрос чисел**: Вначале программа запрашивает два числа у пользователя и пытается выполнить деление. Если пользователь введет некорректные данные, будет поймано исключение `FormatException`.
2. **Обработка исключений**:
   - При делении на ноль возникает `DivideByZeroException`, которая перехватывается в блоке `catch`.
   - В случае ошибки записи в файл будет поймано исключение `IOException`.
3. **Запись в файл**: После успешного деления результат записывается в файл `result.txt`. Если возникает ошибка записи, она будет обработана и выведена в консоль.
4. **Блок `finally`**: Независимо от результата выполнения программы, блок `finally` всегда выполняется, что гарантирует корректное завершение программы.
